{
    DataVersion: 3465,
    size: [17, 14, 17],
    data: [
        {pos: [5, 0, 8], state: "minecraft:gray_concrete"},
        {pos: [6, 0, 7], state: "minecraft:gray_concrete"},
        {pos: [6, 0, 8], state: "minecraft:gray_concrete"},
        {pos: [6, 0, 9], state: "minecraft:gray_concrete"},
        {pos: [7, 0, 6], state: "minecraft:gray_concrete"},
        {pos: [7, 0, 7], state: "minecraft:gray_concrete"},
        {pos: [7, 0, 8], state: "minecraft:gray_concrete"},
        {pos: [7, 0, 9], state: "minecraft:gray_concrete"},
        {pos: [7, 0, 10], state: "minecraft:gray_concrete"},
        {pos: [8, 0, 5], state: "minecraft:gray_concrete"},
        {pos: [8, 0, 6], state: "minecraft:gray_concrete"},
        {pos: [8, 0, 7], state: "minecraft:gray_concrete"},
        {pos: [8, 0, 8], state: "minecraft:gray_concrete"},
        {pos: [8, 0, 9], state: "minecraft:gray_concrete"},
        {pos: [8, 0, 10], state: "minecraft:gray_concrete"},
        {pos: [8, 0, 11], state: "minecraft:gray_concrete"},
        {pos: [9, 0, 6], state: "minecraft:gray_concrete"},
        {pos: [9, 0, 7], state: "minecraft:gray_concrete"},
        {pos: [9, 0, 8], state: "minecraft:gray_concrete"},
        {pos: [9, 0, 9], state: "minecraft:gray_concrete"},
        {pos: [9, 0, 10], state: "minecraft:gray_concrete"},
        {pos: [10, 0, 7], state: "minecraft:gray_concrete"},
        {pos: [10, 0, 8], state: "minecraft:gray_concrete"},
        {pos: [10, 0, 9], state: "minecraft:gray_concrete"},
        {pos: [11, 0, 8], state: "minecraft:gray_concrete"},
        {pos: [1, 1, 6], state: "minecraft:gray_concrete"},
        {pos: [1, 1, 7], state: "minecraft:gray_concrete"},
        {pos: [1, 1, 8], state: "minecraft:gray_concrete"},
        {pos: [1, 1, 9], state: "minecraft:gray_concrete"},
        {pos: [1, 1, 10], state: "minecraft:gray_concrete"},
        {pos: [2, 1, 4], state: "minecraft:gray_concrete"},
        {pos: [2, 1, 5], state: "minecraft:gray_concrete"},
        {pos: [2, 1, 6], state: "minecraft:gray_concrete"},
        {pos: [2, 1, 7], state: "minecraft:white_concrete"},
        {pos: [2, 1, 8], state: "minecraft:pearlescent_froglight{axis:x}"},
        {pos: [2, 1, 9], state: "minecraft:white_concrete"},
        {pos: [2, 1, 10], state: "minecraft:gray_concrete"},
        {pos: [2, 1, 11], state: "minecraft:gray_concrete"},
        {pos: [2, 1, 12], state: "minecraft:gray_concrete"},
        {pos: [3, 1, 3], state: "minecraft:gray_concrete"},
        {pos: [3, 1, 4], state: "minecraft:gray_concrete"},
        {pos: [3, 1, 5], state: "minecraft:white_concrete"},
        {pos: [3, 1, 6], state: "minecraft:white_concrete"},
        {pos: [3, 1, 7], state: "minecraft:white_concrete"},
        {pos: [3, 1, 8], state: "minecraft:gray_concrete"},
        {pos: [3, 1, 9], state: "minecraft:white_concrete"},
        {pos: [3, 1, 10], state: "minecraft:white_concrete"},
        {pos: [3, 1, 11], state: "minecraft:white_concrete"},
        {pos: [3, 1, 12], state: "minecraft:gray_concrete"},
        {pos: [3, 1, 13], state: "minecraft:gray_concrete"},
        {pos: [4, 1, 2], state: "minecraft:gray_concrete"},
        {pos: [4, 1, 3], state: "minecraft:gray_concrete"},
        {pos: [4, 1, 4], state: "minecraft:white_concrete"},
        {pos: [4, 1, 5], state: "minecraft:white_concrete"},
        {pos: [4, 1, 6], state: "minecraft:white_concrete"},
        {pos: [4, 1, 7], state: "minecraft:white_concrete"},
        {pos: [4, 1, 8], state: "minecraft:gray_concrete"},
        {pos: [4, 1, 9], state: "minecraft:white_concrete"},
        {pos: [4, 1, 10], state: "minecraft:white_concrete"},
        {pos: [4, 1, 11], state: "minecraft:white_concrete"},
        {pos: [4, 1, 12], state: "minecraft:white_concrete"},
        {pos: [4, 1, 13], state: "minecraft:gray_concrete"},
        {pos: [4, 1, 14], state: "minecraft:gray_concrete"},
        {pos: [5, 1, 2], state: "minecraft:gray_concrete"},
        {pos: [5, 1, 3], state: "minecraft:white_concrete"},
        {pos: [5, 1, 4], state: "minecraft:white_concrete"},
        {pos: [5, 1, 5], state: "minecraft:white_concrete"},
        {pos: [5, 1, 6], state: "minecraft:gray_concrete"},
        {pos: [5, 1, 7], state: "minecraft:gray_concrete"},
        {pos: [5, 1, 8], state: "minecraft:gray_concrete"},
        {pos: [5, 1, 9], state: "minecraft:gray_concrete"},
        {pos: [5, 1, 10], state: "minecraft:gray_concrete"},
        {pos: [5, 1, 11], state: "minecraft:white_concrete"},
        {pos: [5, 1, 12], state: "minecraft:white_concrete"},
        {pos: [5, 1, 13], state: "minecraft:white_concrete"},
        {pos: [5, 1, 14], state: "minecraft:gray_concrete"},
        {pos: [6, 1, 1], state: "minecraft:gray_concrete"},
        {pos: [6, 1, 2], state: "minecraft:gray_concrete"},
        {pos: [6, 1, 3], state: "minecraft:white_concrete"},
        {pos: [6, 1, 4], state: "minecraft:white_concrete"},
        {pos: [6, 1, 5], state: "minecraft:gray_concrete"},
        {pos: [6, 1, 6], state: "minecraft:gray_concrete"},
        {pos: [6, 1, 7], state: "minecraft:grass_block{snowy:false}"},
        {pos: [6, 1, 8], state: "minecraft:grass_block{snowy:false}"},
        {pos: [6, 1, 9], state: "minecraft:grass_block{snowy:false}"},
        {pos: [6, 1, 10], state: "minecraft:gray_concrete"},
        {pos: [6, 1, 11], state: "minecraft:gray_concrete"},
        {pos: [6, 1, 12], state: "minecraft:white_concrete"},
        {pos: [6, 1, 13], state: "minecraft:white_concrete"},
        {pos: [6, 1, 14], state: "minecraft:gray_concrete"},
        {pos: [6, 1, 15], state: "minecraft:gray_concrete"},
        {pos: [7, 1, 1], state: "minecraft:gray_concrete"},
        {pos: [7, 1, 2], state: "minecraft:white_concrete"},
        {pos: [7, 1, 3], state: "minecraft:white_concrete"},
        {pos: [7, 1, 4], state: "minecraft:white_concrete"},
        {pos: [7, 1, 5], state: "minecraft:gray_concrete"},
        {pos: [7, 1, 6], state: "minecraft:grass_block{snowy:false}"},
        {pos: [7, 1, 7], state: "minecraft:grass_block{snowy:false}"},
        {pos: [7, 1, 8], state: "minecraft:grass_block{snowy:false}"},
        {pos: [7, 1, 9], state: "minecraft:grass_block{snowy:false}"},
        {pos: [7, 1, 10], state: "minecraft:grass_block{snowy:false}"},
        {pos: [7, 1, 11], state: "minecraft:gray_concrete"},
        {pos: [7, 1, 12], state: "minecraft:white_concrete"},
        {pos: [7, 1, 13], state: "minecraft:white_concrete"},
        {pos: [7, 1, 14], state: "minecraft:white_concrete"},
        {pos: [7, 1, 15], state: "minecraft:gray_concrete"},
        {pos: [8, 1, 1], state: "minecraft:gray_concrete"},
        {pos: [8, 1, 2], state: "minecraft:gray_concrete"},
        {pos: [8, 1, 3], state: "minecraft:gray_concrete"},
        {pos: [8, 1, 4], state: "minecraft:gray_concrete"},
        {pos: [8, 1, 5], state: "minecraft:gray_concrete"},
        {pos: [8, 1, 6], state: "minecraft:grass_block{snowy:false}"},
        {pos: [8, 1, 7], state: "minecraft:grass_block{snowy:false}"},
        {pos: [8, 1, 8], state: "minecraft:dirt"},
        {pos: [8, 1, 9], state: "minecraft:grass_block{snowy:false}"},
        {pos: [8, 1, 10], state: "minecraft:grass_block{snowy:false}"},
        {pos: [8, 1, 11], state: "minecraft:gray_concrete"},
        {pos: [8, 1, 12], state: "minecraft:gray_concrete"},
        {pos: [8, 1, 13], state: "minecraft:gray_concrete"},
        {pos: [8, 1, 14], state: "minecraft:pearlescent_froglight{axis:z}"},
        {pos: [8, 1, 15], state: "minecraft:gray_concrete"},
        {pos: [9, 1, 1], state: "minecraft:gray_concrete"},
        {pos: [9, 1, 2], state: "minecraft:white_concrete"},
        {pos: [9, 1, 3], state: "minecraft:white_concrete"},
        {pos: [9, 1, 4], state: "minecraft:white_concrete"},
        {pos: [9, 1, 5], state: "minecraft:gray_concrete"},
        {pos: [9, 1, 6], state: "minecraft:grass_block{snowy:false}"},
        {pos: [9, 1, 7], state: "minecraft:grass_block{snowy:false}"},
        {pos: [9, 1, 8], state: "minecraft:grass_block{snowy:false}"},
        {pos: [9, 1, 9], state: "minecraft:grass_block{snowy:false}"},
        {pos: [9, 1, 10], state: "minecraft:grass_block{snowy:false}"},
        {pos: [9, 1, 11], state: "minecraft:gray_concrete"},
        {pos: [9, 1, 12], state: "minecraft:white_concrete"},
        {pos: [9, 1, 13], state: "minecraft:white_concrete"},
        {pos: [9, 1, 14], state: "minecraft:white_concrete"},
        {pos: [9, 1, 15], state: "minecraft:gray_concrete"},
        {pos: [10, 1, 1], state: "minecraft:gray_concrete"},
        {pos: [10, 1, 2], state: "minecraft:gray_concrete"},
        {pos: [10, 1, 3], state: "minecraft:white_concrete"},
        {pos: [10, 1, 4], state: "minecraft:white_concrete"},
        {pos: [10, 1, 5], state: "minecraft:gray_concrete"},
        {pos: [10, 1, 6], state: "minecraft:gray_concrete"},
        {pos: [10, 1, 7], state: "minecraft:grass_block{snowy:false}"},
        {pos: [10, 1, 8], state: "minecraft:grass_block{snowy:false}"},
        {pos: [10, 1, 9], state: "minecraft:grass_block{snowy:false}"},
        {pos: [10, 1, 10], state: "minecraft:gray_concrete"},
        {pos: [10, 1, 11], state: "minecraft:gray_concrete"},
        {pos: [10, 1, 12], state: "minecraft:white_concrete"},
        {pos: [10, 1, 13], state: "minecraft:white_concrete"},
        {pos: [10, 1, 14], state: "minecraft:gray_concrete"},
        {pos: [10, 1, 15], state: "minecraft:gray_concrete"},
        {pos: [11, 1, 2], state: "minecraft:gray_concrete"},
        {pos: [11, 1, 3], state: "minecraft:white_concrete"},
        {pos: [11, 1, 4], state: "minecraft:white_concrete"},
        {pos: [11, 1, 5], state: "minecraft:white_concrete"},
        {pos: [11, 1, 6], state: "minecraft:gray_concrete"},
        {pos: [11, 1, 7], state: "minecraft:gray_concrete"},
        {pos: [11, 1, 8], state: "minecraft:gray_concrete"},
        {pos: [11, 1, 9], state: "minecraft:gray_concrete"},
        {pos: [11, 1, 10], state: "minecraft:gray_concrete"},
        {pos: [11, 1, 11], state: "minecraft:white_concrete"},
        {pos: [11, 1, 12], state: "minecraft:white_concrete"},
        {pos: [11, 1, 13], state: "minecraft:white_concrete"},
        {pos: [11, 1, 14], state: "minecraft:gray_concrete"},
        {pos: [12, 1, 2], state: "minecraft:gray_concrete"},
        {pos: [12, 1, 3], state: "minecraft:gray_concrete"},
        {pos: [12, 1, 4], state: "minecraft:white_concrete"},
        {pos: [12, 1, 5], state: "minecraft:white_concrete"},
        {pos: [12, 1, 6], state: "minecraft:white_concrete"},
        {pos: [12, 1, 7], state: "minecraft:white_concrete"},
        {pos: [12, 1, 8], state: "minecraft:gray_concrete"},
        {pos: [12, 1, 9], state: "minecraft:white_concrete"},
        {pos: [12, 1, 10], state: "minecraft:white_concrete"},
        {pos: [12, 1, 11], state: "minecraft:white_concrete"},
        {pos: [12, 1, 12], state: "minecraft:white_concrete"},
        {pos: [12, 1, 13], state: "minecraft:gray_concrete"},
        {pos: [12, 1, 14], state: "minecraft:gray_concrete"},
        {pos: [13, 1, 3], state: "minecraft:gray_concrete"},
        {pos: [13, 1, 4], state: "minecraft:gray_concrete"},
        {pos: [13, 1, 5], state: "minecraft:white_concrete"},
        {pos: [13, 1, 6], state: "minecraft:white_concrete"},
        {pos: [13, 1, 7], state: "minecraft:white_concrete"},
        {pos: [13, 1, 8], state: "minecraft:gray_concrete"},
        {pos: [13, 1, 9], state: "minecraft:white_concrete"},
        {pos: [13, 1, 10], state: "minecraft:white_concrete"},
        {pos: [13, 1, 11], state: "minecraft:white_concrete"},
        {pos: [13, 1, 12], state: "minecraft:gray_concrete"},
        {pos: [13, 1, 13], state: "minecraft:gray_concrete"},
        {pos: [14, 1, 4], state: "minecraft:gray_concrete"},
        {pos: [14, 1, 5], state: "minecraft:gray_concrete"},
        {pos: [14, 1, 6], state: "minecraft:gray_concrete"},
        {pos: [14, 1, 7], state: "minecraft:white_concrete"},
        {pos: [14, 1, 8], state: "minecraft:pearlescent_froglight{axis:x}"},
        {pos: [14, 1, 9], state: "minecraft:white_concrete"},
        {pos: [14, 1, 10], state: "minecraft:gray_concrete"},
        {pos: [14, 1, 11], state: "minecraft:gray_concrete"},
        {pos: [14, 1, 12], state: "minecraft:gray_concrete"},
        {pos: [15, 1, 6], state: "minecraft:gray_concrete"},
        {pos: [15, 1, 7], state: "minecraft:gray_concrete"},
        {pos: [15, 1, 8], state: "minecraft:gray_concrete"},
        {pos: [15, 1, 9], state: "minecraft:gray_concrete"},
        {pos: [15, 1, 10], state: "minecraft:gray_concrete"},
        {pos: [6, 2, 2], state: "minecraft:gray_concrete"},
        {pos: [6, 2, 3], state: "minecraft:gray_concrete"},
        {pos: [6, 2, 4], state: "minecraft:gray_concrete"},
        {pos: [7, 2, 2], state: "minecraft:gray_concrete"},
        {pos: [7, 2, 3], state: "simple_resource_generators:random_ore_block_generator_placement{facing:south}"},
        {pos: [8, 2, 2], state: "minecraft:gray_concrete"},
        {pos: [8, 2, 3], state: "simple_resource_generators:simple_lava_condenser{facing:south}", nbt: {ForgeCaps: {}, Items: [], fluidTank: {Amount: 0, FluidName: "minecraft:empty"}, id: "simple_resource_generators:simple_lava_condenser"}},
        {pos: [8, 2, 8], state: "gtceu:rubber_log{axis:y,natural:true}"},
        {pos: [8, 2, 13], state: "minecraft:barrel{facing:north,open:false}", nbt: {ForgeCaps: {}, Items: [{Count: 1b, Slot: 1b, id: "ex_hammers:netherite_hammer", tag: {Damage: 0}}, {Count: 1b, Slot: 2b, id: "ae2:portable_item_cell_16k", tag: {internalCurrentPower: 20000.0d}},{Count: 1b, Slot: 3b, id: "cobblefordays:tier_2",}, {Count: 1b, Slot: 4b, id: "rfd:dirt_gen_tier_2",}, {Count: 2b, Slot: 5b, id: "gtceu:lv_super_chest"}], id: "minecraft:barrel"}},
        {pos: [9, 2, 2], state: "minecraft:gray_concrete"},
        {pos: [9, 2, 3], state: "simple_resource_generators:raw_conversion_generator{facing:south}", nbt: {ForgeCaps: {}, Items: [{Count: 1b, Slot: 0b, id: "gtceu:raw_coal"}], id: "simple_resource_generators:raw_conversion_generator"}},
        {pos: [10, 2, 2], state: "minecraft:gray_concrete"},
        {pos: [10, 2, 3], state: "minecraft:gray_concrete"},
        {pos: [10, 2, 4], state: "minecraft:gray_concrete"},
        {pos: [6, 3, 2], state: "minecraft:gray_concrete"},
        {pos: [6, 3, 3], state: "minecraft:gray_concrete"},
        {pos: [6, 3, 4], state: "minecraft:gray_concrete"},
        {pos: [7, 3, 2], state: "minecraft:gray_concrete"},
        {pos: [7, 3, 3], state: "gtceu:scheelite_ore"},
        {pos: [8, 3, 2], state: "minecraft:gray_concrete"},
        {pos: [8, 3, 3], state: "simple_resource_generators:simple_water_condenser{facing:south}", nbt: {ForgeCaps: {}, Items: [], fluidTank: {Amount: 0, FluidName: "minecraft:empty"}, id: "simple_resource_generators:simple_water_condenser"}},
        {pos: [8, 3, 8], state: "gtceu:rubber_log{axis:y,natural:true}"},
        {pos: [9, 3, 2], state: "minecraft:gray_concrete"},
        {pos: [9, 3, 3], state: "minecraft:deepslate_coal_ore"},
        {pos: [10, 3, 2], state: "minecraft:gray_concrete"},
        {pos: [10, 3, 3], state: "minecraft:gray_concrete"},
        {pos: [10, 3, 4], state: "minecraft:gray_concrete"},
        {pos: [6, 4, 2], state: "minecraft:gray_concrete"},
        {pos: [6, 4, 3], state: "minecraft:gray_concrete"},
        {pos: [6, 4, 4], state: "minecraft:gray_concrete"},
        {pos: [7, 4, 2], state: "minecraft:gray_concrete"},
        {pos: [7, 4, 3], state: "minecraft:gray_concrete"},
        {pos: [7, 4, 4], state: "copycats:copycat_stairs{facing:west,half:top,shape:straight,waterlogged:false}", nbt: {EnableCT: 1b, ForgeCaps: {}, Item: {Count: 1b, id: "minecraft:gray_concrete"}, Material: {Name: "minecraft:gray_concrete"}, id: "create:copycat"}},
        {pos: [8, 4, 2], state: "minecraft:gray_concrete"},
        {pos: [8, 4, 3], state: "charginggadgets:charging_station{facing:south}", nbt: {counter: 0, energy: {energy: 0}, id: "charginggadgets:charging_station_tile", inv: {Items: [], Size: 2}, maxburn: 0}},
        {pos: [8, 4, 8], state: "gtceu:rubber_log{axis:y,natural:true}"},
        {pos: [9, 4, 2], state: "minecraft:gray_concrete"},
        {pos: [9, 4, 3], state: "minecraft:gray_concrete"},
        {pos: [9, 4, 4], state: "copycats:copycat_stairs{facing:east,half:top,shape:straight,waterlogged:false}", nbt: {EnableCT: 1b, ForgeCaps: {}, Item: {Count: 1b, id: "minecraft:gray_concrete"}, Material: {Name: "minecraft:gray_concrete"}, id: "create:copycat"}},
        {pos: [10, 4, 2], state: "minecraft:gray_concrete"},
        {pos: [10, 4, 3], state: "minecraft:gray_concrete"},
        {pos: [10, 4, 4], state: "minecraft:gray_concrete"},
        {pos: [6, 5, 2], state: "copycats:copycat_stairs{facing:east,half:bottom,shape:outer_right,waterlogged:false}", nbt: {EnableCT: 1b, ForgeCaps: {}, Item: {Count: 1b, id: "minecraft:gray_concrete"}, Material: {Name: "minecraft:gray_concrete"}, id: "create:copycat"}},
        {pos: [6, 5, 3], state: "copycats:copycat_stairs{facing:east,half:bottom,shape:straight,waterlogged:false}", nbt: {EnableCT: 1b, ForgeCaps: {}, Item: {Count: 1b, id: "minecraft:gray_concrete"}, Material: {Name: "minecraft:gray_concrete"}, id: "create:copycat"}},
        {pos: [6, 5, 4], state: "copycats:copycat_stairs{facing:east,half:bottom,shape:straight,waterlogged:false}", nbt: {EnableCT: 1b, ForgeCaps: {}, Item: {Count: 1b, id: "minecraft:gray_concrete"}, Material: {Name: "minecraft:gray_concrete"}, id: "create:copycat"}},
        {pos: [7, 5, 2], state: "copycats:copycat_stairs{facing:south,half:bottom,shape:straight,waterlogged:false}", nbt: {EnableCT: 1b, ForgeCaps: {}, Item: {Count: 1b, id: "minecraft:gray_concrete"}, Material: {Name: "minecraft:gray_concrete"}, id: "create:copycat"}},
        {pos: [7, 5, 3], state: "minecraft:gray_concrete"},
        {pos: [7, 5, 4], state: "minecraft:gray_concrete"},
        {pos: [8, 5, 2], state: "copycats:copycat_stairs{facing:south,half:bottom,shape:straight,waterlogged:false}", nbt: {EnableCT: 1b, ForgeCaps: {}, Item: {Count: 1b, id: "minecraft:gray_concrete"}, Material: {Name: "minecraft:gray_concrete"}, id: "create:copycat"}},
        {pos: [8, 5, 3], state: "minecraft:gray_concrete"},
        {pos: [8, 5, 4], state: "minecraft:gray_concrete"},
        {pos: [8, 5, 8], state: "gtceu:rubber_log{axis:y,natural:true}"},
        {pos: [8, 5, 9], state: "gtceu:rubber_log{axis:y,natural:true}"},
        {pos: [9, 5, 2], state: "copycats:copycat_stairs{facing:south,half:bottom,shape:straight,waterlogged:false}", nbt: {EnableCT: 1b, ForgeCaps: {}, Item: {Count: 1b, id: "minecraft:gray_concrete"}, Material: {Name: "minecraft:gray_concrete"}, id: "create:copycat"}},
        {pos: [9, 5, 3], state: "minecraft:gray_concrete"},
        {pos: [9, 5, 4], state: "minecraft:gray_concrete"},
        {pos: [10, 5, 2], state: "copycats:copycat_stairs{facing:west,half:bottom,shape:outer_left,waterlogged:false}", nbt: {EnableCT: 1b, ForgeCaps: {}, Item: {Count: 1b, id: "minecraft:gray_concrete"}, Material: {Name: "minecraft:gray_concrete"}, id: "create:copycat"}},
        {pos: [10, 5, 3], state: "copycats:copycat_stairs{facing:west,half:bottom,shape:straight,waterlogged:false}", nbt: {EnableCT: 1b, ForgeCaps: {}, Item: {Count: 1b, id: "minecraft:gray_concrete"}, Material: {Name: "minecraft:gray_concrete"}, id: "create:copycat"}},
        {pos: [10, 5, 4], state: "copycats:copycat_stairs{facing:west,half:bottom,shape:straight,waterlogged:false}", nbt: {EnableCT: 1b, ForgeCaps: {}, Item: {Count: 1b, id: "minecraft:gray_concrete"}, Material: {Name: "minecraft:gray_concrete"}, id: "create:copycat"}},
        {pos: [8, 6, 8], state: "gtceu:rubber_log{axis:y,natural:true}"},
        {pos: [8, 6, 10], state: "gtceu:rubber_log{axis:y,natural:true}"},
        {pos: [5, 7, 11], state: "gtceu:rubber_leaves{distance:3,persistent:false,waterlogged:false}"},
        {pos: [6, 7, 9], state: "gtceu:rubber_leaves{distance:4,persistent:false,waterlogged:false}"},
        {pos: [6, 7, 10], state: "gtceu:rubber_leaves{distance:3,persistent:false,waterlogged:false}"},
        {pos: [6, 7, 11], state: "gtceu:rubber_leaves{distance:2,persistent:false,waterlogged:false}"},
        {pos: [6, 7, 12], state: "gtceu:rubber_leaves{distance:3,persistent:false,waterlogged:false}"},
        {pos: [6, 7, 13], state: "gtceu:rubber_leaves{distance:4,persistent:false,waterlogged:false}"},
        {pos: [7, 7, 9], state: "gtceu:rubber_leaves{distance:3,persistent:false,waterlogged:false}"},
        {pos: [7, 7, 10], state: "gtceu:rubber_leaves{distance:2,persistent:false,waterlogged:false}"},
        {pos: [7, 7, 11], state: "gtceu:rubber_leaves{distance:1,persistent:false,waterlogged:false}"},
        {pos: [7, 7, 12], state: "gtceu:rubber_leaves{distance:2,persistent:false,waterlogged:false}"},
        {pos: [7, 7, 13], state: "gtceu:rubber_leaves{distance:3,persistent:false,waterlogged:false}"},
        {pos: [8, 7, 8], state: "gtceu:rubber_leaves{distance:1,persistent:false,waterlogged:false}"},
        {pos: [8, 7, 9], state: "gtceu:rubber_leaves{distance:2,persistent:false,waterlogged:false}"},
        {pos: [8, 7, 10], state: "gtceu:rubber_leaves{distance:1,persistent:false,waterlogged:false}"},
        {pos: [8, 7, 11], state: "gtceu:rubber_log{axis:y,natural:true}"},
        {pos: [8, 7, 12], state: "gtceu:rubber_leaves{distance:1,persistent:false,waterlogged:false}"},
        {pos: [8, 7, 13], state: "gtceu:rubber_leaves{distance:2,persistent:false,waterlogged:false}"},
        {pos: [8, 7, 14], state: "gtceu:rubber_leaves{distance:3,persistent:false,waterlogged:false}"},
        {pos: [9, 7, 8], state: "gtceu:rubber_log{axis:y,natural:true}"},
        {pos: [9, 7, 9], state: "gtceu:rubber_leaves{distance:1,persistent:false,waterlogged:false}"},
        {pos: [9, 7, 10], state: "gtceu:rubber_leaves{distance:2,persistent:false,waterlogged:false}"},
        {pos: [9, 7, 11], state: "gtceu:rubber_leaves{distance:1,persistent:false,waterlogged:false}"},
        {pos: [9, 7, 12], state: "gtceu:rubber_leaves{distance:2,persistent:false,waterlogged:false}"},
        {pos: [9, 7, 13], state: "gtceu:rubber_leaves{distance:3,persistent:false,waterlogged:false}"},
        {pos: [10, 7, 9], state: "gtceu:rubber_leaves{distance:2,persistent:false,waterlogged:false}"},
        {pos: [10, 7, 10], state: "gtceu:rubber_leaves{distance:3,persistent:false,waterlogged:false}"},
        {pos: [10, 7, 11], state: "gtceu:rubber_leaves{distance:2,persistent:false,waterlogged:false}"},
        {pos: [10, 7, 12], state: "gtceu:rubber_leaves{distance:3,persistent:false,waterlogged:false}"},
        {pos: [10, 7, 13], state: "gtceu:rubber_leaves{distance:4,persistent:false,waterlogged:false}"},
        {pos: [11, 7, 11], state: "gtceu:rubber_leaves{distance:3,persistent:false,waterlogged:false}"},
        {pos: [6, 8, 11], state: "gtceu:rubber_leaves{distance:3,persistent:false,waterlogged:false}"},
        {pos: [7, 8, 10], state: "gtceu:rubber_leaves{distance:3,persistent:false,waterlogged:false}"},
        {pos: [7, 8, 11], state: "gtceu:rubber_leaves{distance:2,persistent:false,waterlogged:false}"},
        {pos: [7, 8, 12], state: "gtceu:rubber_leaves{distance:3,persistent:false,waterlogged:false}"},
        {pos: [8, 8, 9], state: "gtceu:rubber_leaves{distance:3,persistent:false,waterlogged:false}"},
        {pos: [8, 8, 10], state: "gtceu:rubber_leaves{distance:2,persistent:false,waterlogged:false}"},
        {pos: [8, 8, 11], state: "gtceu:rubber_leaves{distance:1,persistent:false,waterlogged:false}"},
        {pos: [8, 8, 12], state: "gtceu:rubber_leaves{distance:2,persistent:false,waterlogged:false}"},
        {pos: [8, 8, 13], state: "gtceu:rubber_leaves{distance:3,persistent:false,waterlogged:false}"},
        {pos: [9, 8, 10], state: "gtceu:rubber_leaves{distance:3,persistent:false,waterlogged:false}"},
        {pos: [9, 8, 11], state: "gtceu:rubber_leaves{distance:2,persistent:false,waterlogged:false}"},
        {pos: [9, 8, 12], state: "gtceu:rubber_leaves{distance:3,persistent:false,waterlogged:false}"},
        {pos: [10, 8, 8], state: "gtceu:rubber_log{axis:y,natural:true}"},
        {pos: [10, 8, 11], state: "gtceu:rubber_leaves{distance:3,persistent:false,waterlogged:false}"},
        {pos: [6, 9, 8], state: "gtceu:rubber_leaves{distance:4,persistent:false,waterlogged:false}"},
        {pos: [7, 9, 6], state: "gtceu:rubber_leaves{distance:5,persistent:false,waterlogged:false}"},
        {pos: [7, 9, 7], state: "gtceu:rubber_leaves{distance:4,persistent:false,waterlogged:false}"},
        {pos: [7, 9, 8], state: "gtceu:rubber_leaves{distance:3,persistent:false,waterlogged:false}"},
        {pos: [7, 9, 9], state: "gtceu:rubber_leaves{distance:4,persistent:false,waterlogged:false}"},
        {pos: [7, 9, 10], state: "gtceu:rubber_leaves{distance:4,persistent:false,waterlogged:false}"},
        {pos: [7, 9, 11], state: "gtceu:rubber_leaves{distance:3,persistent:false,waterlogged:false}"},
        {pos: [8, 9, 5], state: "gtceu:rubber_leaves{distance:5,persistent:false,waterlogged:false}"},
        {pos: [8, 9, 6], state: "gtceu:rubber_leaves{distance:4,persistent:false,waterlogged:false}"},
        {pos: [8, 9, 7], state: "gtceu:rubber_leaves{distance:3,persistent:false,waterlogged:false}"},
        {pos: [8, 9, 8], state: "gtceu:rubber_leaves{distance:2,persistent:false,waterlogged:false}"},
        {pos: [8, 9, 9], state: "gtceu:rubber_leaves{distance:3,persistent:false,waterlogged:false}"},
        {pos: [8, 9, 10], state: "gtceu:rubber_leaves{distance:3,persistent:false,waterlogged:false}"},
        {pos: [8, 9, 11], state: "gtceu:rubber_leaves{distance:2,persistent:false,waterlogged:false}"},
        {pos: [8, 9, 12], state: "gtceu:rubber_leaves{distance:3,persistent:false,waterlogged:false}"},
        {pos: [9, 9, 5], state: "gtceu:rubber_leaves{distance:4,persistent:false,waterlogged:false}"},
        {pos: [9, 9, 6], state: "gtceu:rubber_leaves{distance:3,persistent:false,waterlogged:false}"},
        {pos: [9, 9, 7], state: "gtceu:rubber_leaves{distance:2,persistent:false,waterlogged:false}"},
        {pos: [9, 9, 8], state: "gtceu:rubber_leaves{distance:1,persistent:false,waterlogged:false}"},
        {pos: [9, 9, 9], state: "gtceu:rubber_leaves{distance:2,persistent:false,waterlogged:false}"},
        {pos: [9, 9, 10], state: "gtceu:rubber_leaves{distance:3,persistent:false,waterlogged:false}"},
        {pos: [9, 9, 11], state: "gtceu:rubber_leaves{distance:3,persistent:false,waterlogged:false}"},
        {pos: [10, 9, 4], state: "gtceu:rubber_leaves{distance:4,persistent:false,waterlogged:false}"},
        {pos: [10, 9, 5], state: "gtceu:rubber_leaves{distance:3,persistent:false,waterlogged:false}"},
        {pos: [10, 9, 6], state: "gtceu:rubber_leaves{distance:2,persistent:false,waterlogged:false}"},
        {pos: [10, 9, 7], state: "gtceu:rubber_leaves{distance:1,persistent:false,waterlogged:false}"},
        {pos: [10, 9, 8], state: "gtceu:rubber_log{axis:y,natural:true}"},
        {pos: [10, 9, 9], state: "gtceu:rubber_leaves{distance:1,persistent:false,waterlogged:false}"},
        {pos: [10, 9, 10], state: "gtceu:rubber_leaves{distance:2,persistent:false,waterlogged:false}"},
        {pos: [10, 9, 11], state: "gtceu:rubber_leaves{distance:3,persistent:false,waterlogged:false}"},
        {pos: [10, 9, 12], state: "gtceu:rubber_leaves{distance:4,persistent:false,waterlogged:false}"},
        {pos: [11, 9, 5], state: "gtceu:rubber_leaves{distance:4,persistent:false,waterlogged:false}"},
        {pos: [11, 9, 6], state: "gtceu:rubber_leaves{distance:3,persistent:false,waterlogged:false}"},
        {pos: [11, 9, 7], state: "gtceu:rubber_leaves{distance:2,persistent:false,waterlogged:false}"},
        {pos: [11, 9, 8], state: "gtceu:rubber_leaves{distance:1,persistent:false,waterlogged:false}"},
        {pos: [11, 9, 9], state: "gtceu:rubber_leaves{distance:2,persistent:false,waterlogged:false}"},
        {pos: [11, 9, 10], state: "gtceu:rubber_leaves{distance:3,persistent:false,waterlogged:false}"},
        {pos: [11, 9, 11], state: "gtceu:rubber_leaves{distance:4,persistent:false,waterlogged:false}"},
        {pos: [12, 9, 5], state: "gtceu:rubber_leaves{distance:5,persistent:false,waterlogged:false}"},
        {pos: [12, 9, 6], state: "gtceu:rubber_leaves{distance:4,persistent:false,waterlogged:false}"},
        {pos: [12, 9, 7], state: "gtceu:rubber_leaves{distance:3,persistent:false,waterlogged:false}"},
        {pos: [12, 9, 8], state: "gtceu:rubber_leaves{distance:2,persistent:false,waterlogged:false}"},
        {pos: [12, 9, 9], state: "gtceu:rubber_leaves{distance:3,persistent:false,waterlogged:false}"},
        {pos: [12, 9, 10], state: "gtceu:rubber_leaves{distance:4,persistent:false,waterlogged:false}"},
        {pos: [12, 9, 11], state: "gtceu:rubber_leaves{distance:5,persistent:false,waterlogged:false}"},
        {pos: [13, 9, 6], state: "gtceu:rubber_leaves{distance:5,persistent:false,waterlogged:false}"},
        {pos: [13, 9, 7], state: "gtceu:rubber_leaves{distance:4,persistent:false,waterlogged:false}"},
        {pos: [13, 9, 8], state: "gtceu:rubber_leaves{distance:3,persistent:false,waterlogged:false}"},
        {pos: [13, 9, 9], state: "gtceu:rubber_leaves{distance:4,persistent:false,waterlogged:false}"},
        {pos: [13, 9, 10], state: "gtceu:rubber_leaves{distance:5,persistent:false,waterlogged:false}"},
        {pos: [14, 9, 8], state: "gtceu:rubber_leaves{distance:4,persistent:false,waterlogged:false}"},
        {pos: [7, 10, 8], state: "gtceu:rubber_leaves{distance:4,persistent:false,waterlogged:false}"},
        {pos: [8, 10, 6], state: "gtceu:rubber_leaves{distance:5,persistent:false,waterlogged:false}"},
        {pos: [8, 10, 7], state: "gtceu:rubber_leaves{distance:4,persistent:false,waterlogged:false}"},
        {pos: [8, 10, 8], state: "gtceu:rubber_leaves{distance:3,persistent:false,waterlogged:false}"},
        {pos: [8, 10, 9], state: "gtceu:rubber_leaves{distance:4,persistent:false,waterlogged:false}"},
        {pos: [8, 10, 10], state: "gtceu:rubber_leaves{distance:4,persistent:false,waterlogged:false}"},
        {pos: [9, 10, 6], state: "gtceu:rubber_leaves{distance:4,persistent:false,waterlogged:false}"},
        {pos: [9, 10, 7], state: "gtceu:rubber_leaves{distance:3,persistent:false,waterlogged:false}"},
        {pos: [9, 10, 8], state: "gtceu:rubber_leaves{distance:2,persistent:false,waterlogged:false}"},
        {pos: [9, 10, 9], state: "gtceu:rubber_leaves{distance:3,persistent:false,waterlogged:false}"},
        {pos: [9, 10, 10], state: "gtceu:rubber_leaves{distance:4,persistent:false,waterlogged:false}"},
        {pos: [10, 10, 5], state: "gtceu:rubber_leaves{distance:4,persistent:false,waterlogged:false}"},
        {pos: [10, 10, 6], state: "gtceu:rubber_leaves{distance:3,persistent:false,waterlogged:false}"},
        {pos: [10, 10, 7], state: "gtceu:rubber_leaves{distance:2,persistent:false,waterlogged:false}"},
        {pos: [10, 10, 8], state: "gtceu:rubber_leaves{distance:1,persistent:false,waterlogged:false}"},
        {pos: [10, 10, 9], state: "gtceu:rubber_leaves{distance:2,persistent:false,waterlogged:false}"},
        {pos: [10, 10, 10], state: "gtceu:rubber_leaves{distance:3,persistent:false,waterlogged:false}"},
        {pos: [10, 10, 11], state: "gtceu:rubber_leaves{distance:4,persistent:false,waterlogged:false}"},
        {pos: [11, 10, 6], state: "gtceu:rubber_leaves{distance:4,persistent:false,waterlogged:false}"},
        {pos: [11, 10, 7], state: "gtceu:rubber_leaves{distance:3,persistent:false,waterlogged:false}"},
        {pos: [11, 10, 8], state: "gtceu:rubber_leaves{distance:2,persistent:false,waterlogged:false}"},
        {pos: [11, 10, 9], state: "gtceu:rubber_leaves{distance:3,persistent:false,waterlogged:false}"},
        {pos: [11, 10, 10], state: "gtceu:rubber_leaves{distance:4,persistent:false,waterlogged:false}"},
        {pos: [12, 10, 6], state: "gtceu:rubber_leaves{distance:5,persistent:false,waterlogged:false}"},
        {pos: [12, 10, 7], state: "gtceu:rubber_leaves{distance:4,persistent:false,waterlogged:false}"},
        {pos: [12, 10, 8], state: "gtceu:rubber_leaves{distance:3,persistent:false,waterlogged:false}"},
        {pos: [12, 10, 9], state: "gtceu:rubber_leaves{distance:4,persistent:false,waterlogged:false}"},
        {pos: [12, 10, 10], state: "gtceu:rubber_leaves{distance:5,persistent:false,waterlogged:false}"},
        {pos: [13, 10, 8], state: "gtceu:rubber_leaves{distance:4,persistent:false,waterlogged:false}"}
    ],
    entities: [],
    palette: [
        "minecraft:gray_concrete",
        "minecraft:white_concrete",
        "minecraft:pearlescent_froglight{axis:x}",
        "minecraft:grass_block{snowy:false}",
        "minecraft:dirt",
        "minecraft:pearlescent_froglight{axis:z}",
        "simple_resource_generators:random_ore_block_generator_placement{facing:south}",
        "gtceu:rubber_log{axis:y,natural:true}",
        "gtceu:scheelite_ore",
        "minecraft:deepslate_coal_ore",
        "gtceu:rubber_leaves{distance:3,persistent:false,waterlogged:false}",
        "gtceu:rubber_leaves{distance:4,persistent:false,waterlogged:false}",
        "gtceu:rubber_leaves{distance:2,persistent:false,waterlogged:false}",
        "gtceu:rubber_leaves{distance:1,persistent:false,waterlogged:false}",
        "gtceu:rubber_leaves{distance:5,persistent:false,waterlogged:false}",
        "simple_resource_generators:simple_lava_condenser{facing:south}",
        "minecraft:barrel{facing:north,open:false}",
        "simple_resource_generators:raw_conversion_generator{facing:south}",
        "simple_resource_generators:simple_water_condenser{facing:south}",
        "copycats:copycat_stairs{facing:west,half:top,shape:straight,waterlogged:false}",
        "charginggadgets:charging_station{facing:south}",
        "copycats:copycat_stairs{facing:east,half:top,shape:straight,waterlogged:false}",
        "copycats:copycat_stairs{facing:east,half:bottom,shape:outer_right,waterlogged:false}",
        "copycats:copycat_stairs{facing:east,half:bottom,shape:straight,waterlogged:false}",
        "copycats:copycat_stairs{facing:south,half:bottom,shape:straight,waterlogged:false}",
        "copycats:copycat_stairs{facing:west,half:bottom,shape:outer_left,waterlogged:false}",
        "copycats:copycat_stairs{facing:west,half:bottom,shape:straight,waterlogged:false}"
    ],
    Railways_DataVersion: 2
}